<?xml version="1.0" encoding="UTF-8"?>
<testng-results skipped="5" failed="2" ignored="0" total="7" passed="0">
  <reporter-output>
  </reporter-output>
  <suite name="用户管理系统测试套件" duration-ms="55692" started-at="2021-01-25T09:29:59 CST" finished-at="2021-01-25T09:30:54 CST">
    <groups>
      <group name="loginTrue">
        <method signature="LoginTest.loginTrue()[pri:0, instance:com.course.cases.LoginTest@31dc339b]" name="loginTrue" class="com.course.cases.LoginTest"/>
      </group> <!-- loginTrue -->
      <group name="loginFalse">
        <method signature="LoginTest.loginFalse()[pri:0, instance:com.course.cases.LoginTest@31dc339b]" name="loginFalse" class="com.course.cases.LoginTest"/>
      </group> <!-- loginFalse -->
    </groups>
    <test name="用户管理系统测试用例" duration-ms="55692" started-at="2021-01-25T09:29:59 CST" finished-at="2021-01-25T09:30:54 CST">
      <class name="com.course.cases.UpdateUserInfoTest">
        <test-method status="SKIP" signature="updateUserInfo()[pri:0, instance:com.course.cases.UpdateUserInfoTest@21213b92]" name="updateUserInfo" duration-ms="0" depends-on-groups="loginTrue" started-at="2021-01-25T09:30:54 CST" description="更改用户信息" finished-at="2021-01-25T09:30:54 CST">
          <exception class="java.lang.Throwable">
            <message>
              <![CDATA[Method UpdateUserInfoTest.updateUserInfo()[pri:0, instance:com.course.cases.UpdateUserInfoTest@21213b92] depends on not successfully finished methods in group "loginTrue"]]>
            </message>
            <full-stacktrace>
              <![CDATA[java.lang.Throwable: Method UpdateUserInfoTest.updateUserInfo()[pri:0, instance:com.course.cases.UpdateUserInfoTest@21213b92] depends on not successfully finished methods in group "loginTrue"
at org.testng.internal.TestInvoker.invokeTestMethods(TestInvoker.java:102)
at org.testng.internal.TestMethodWorker.invokeTestMethods(TestMethodWorker.java:146)
at org.testng.internal.TestMethodWorker.run(TestMethodWorker.java:128)
at java.util.ArrayList.forEach(ArrayList.java:1257)
at org.testng.TestRunner.privateRun(TestRunner.java:764)
at org.testng.TestRunner.run(TestRunner.java:585)
at org.testng.SuiteRunner.runTest(SuiteRunner.java:384)
at org.testng.SuiteRunner.runSequentially(SuiteRunner.java:378)
at org.testng.SuiteRunner.privateRun(SuiteRunner.java:337)
at org.testng.SuiteRunner.run(SuiteRunner.java:286)
at org.testng.SuiteRunnerWorker.runSuite(SuiteRunnerWorker.java:53)
at org.testng.SuiteRunnerWorker.run(SuiteRunnerWorker.java:96)
at org.testng.TestNG.runSuitesSequentially(TestNG.java:1218)
at org.testng.TestNG.runSuitesLocally(TestNG.java:1140)
at org.testng.TestNG.runSuites(TestNG.java:1069)
at org.testng.TestNG.run(TestNG.java:1037)
at org.apache.maven.surefire.testng.TestNGExecutor.run(TestNGExecutor.java:284)
at org.apache.maven.surefire.testng.TestNGXmlTestSuite.execute(TestNGXmlTestSuite.java:75)
at org.apache.maven.surefire.testng.TestNGProvider.invoke(TestNGProvider.java:119)
at org.apache.maven.surefire.booter.ForkedBooter.runSuitesInProcess(ForkedBooter.java:428)
at org.apache.maven.surefire.booter.ForkedBooter.execute(ForkedBooter.java:162)
at org.apache.maven.surefire.booter.ForkedBooter.run(ForkedBooter.java:562)
at org.apache.maven.surefire.booter.ForkedBooter.main(ForkedBooter.java:548)
]]>
            </full-stacktrace>
          </exception> <!-- java.lang.Throwable -->
          <reporter-output>
          </reporter-output>
        </test-method> <!-- updateUserInfo -->
        <test-method status="SKIP" signature="deleteUserInfo()[pri:0, instance:com.course.cases.UpdateUserInfoTest@21213b92]" name="deleteUserInfo" duration-ms="0" depends-on-groups="loginTrue" started-at="2021-01-25T09:30:54 CST" description="删除用户信息" finished-at="2021-01-25T09:30:54 CST">
          <exception class="java.lang.Throwable">
            <message>
              <![CDATA[Method UpdateUserInfoTest.deleteUserInfo()[pri:0, instance:com.course.cases.UpdateUserInfoTest@21213b92] depends on not successfully finished methods in group "loginTrue"]]>
            </message>
            <full-stacktrace>
              <![CDATA[java.lang.Throwable: Method UpdateUserInfoTest.deleteUserInfo()[pri:0, instance:com.course.cases.UpdateUserInfoTest@21213b92] depends on not successfully finished methods in group "loginTrue"
at org.testng.internal.TestInvoker.invokeTestMethods(TestInvoker.java:102)
at org.testng.internal.TestMethodWorker.invokeTestMethods(TestMethodWorker.java:146)
at org.testng.internal.TestMethodWorker.run(TestMethodWorker.java:128)
at java.util.ArrayList.forEach(ArrayList.java:1257)
at org.testng.TestRunner.privateRun(TestRunner.java:764)
at org.testng.TestRunner.run(TestRunner.java:585)
at org.testng.SuiteRunner.runTest(SuiteRunner.java:384)
at org.testng.SuiteRunner.runSequentially(SuiteRunner.java:378)
at org.testng.SuiteRunner.privateRun(SuiteRunner.java:337)
at org.testng.SuiteRunner.run(SuiteRunner.java:286)
at org.testng.SuiteRunnerWorker.runSuite(SuiteRunnerWorker.java:53)
at org.testng.SuiteRunnerWorker.run(SuiteRunnerWorker.java:96)
at org.testng.TestNG.runSuitesSequentially(TestNG.java:1218)
at org.testng.TestNG.runSuitesLocally(TestNG.java:1140)
at org.testng.TestNG.runSuites(TestNG.java:1069)
at org.testng.TestNG.run(TestNG.java:1037)
at org.apache.maven.surefire.testng.TestNGExecutor.run(TestNGExecutor.java:284)
at org.apache.maven.surefire.testng.TestNGXmlTestSuite.execute(TestNGXmlTestSuite.java:75)
at org.apache.maven.surefire.testng.TestNGProvider.invoke(TestNGProvider.java:119)
at org.apache.maven.surefire.booter.ForkedBooter.runSuitesInProcess(ForkedBooter.java:428)
at org.apache.maven.surefire.booter.ForkedBooter.execute(ForkedBooter.java:162)
at org.apache.maven.surefire.booter.ForkedBooter.run(ForkedBooter.java:562)
at org.apache.maven.surefire.booter.ForkedBooter.main(ForkedBooter.java:548)
]]>
            </full-stacktrace>
          </exception> <!-- java.lang.Throwable -->
          <reporter-output>
          </reporter-output>
        </test-method> <!-- deleteUserInfo -->
      </class> <!-- com.course.cases.UpdateUserInfoTest -->
      <class name="com.course.cases.GetUserInfoTest">
        <test-method status="SKIP" signature="getUserInfo()[pri:0, instance:com.course.cases.GetUserInfoTest@31610302]" name="getUserInfo" duration-ms="0" depends-on-groups="loginTrue" started-at="2021-01-25T09:30:54 CST" description="获取userId为2的用户信息" finished-at="2021-01-25T09:30:54 CST">
          <exception class="java.lang.Throwable">
            <message>
              <![CDATA[Method GetUserInfoTest.getUserInfo()[pri:0, instance:com.course.cases.GetUserInfoTest@31610302] depends on not successfully finished methods in group "loginTrue"]]>
            </message>
            <full-stacktrace>
              <![CDATA[java.lang.Throwable: Method GetUserInfoTest.getUserInfo()[pri:0, instance:com.course.cases.GetUserInfoTest@31610302] depends on not successfully finished methods in group "loginTrue"
at org.testng.internal.TestInvoker.invokeTestMethods(TestInvoker.java:102)
at org.testng.internal.TestMethodWorker.invokeTestMethods(TestMethodWorker.java:146)
at org.testng.internal.TestMethodWorker.run(TestMethodWorker.java:128)
at java.util.ArrayList.forEach(ArrayList.java:1257)
at org.testng.TestRunner.privateRun(TestRunner.java:764)
at org.testng.TestRunner.run(TestRunner.java:585)
at org.testng.SuiteRunner.runTest(SuiteRunner.java:384)
at org.testng.SuiteRunner.runSequentially(SuiteRunner.java:378)
at org.testng.SuiteRunner.privateRun(SuiteRunner.java:337)
at org.testng.SuiteRunner.run(SuiteRunner.java:286)
at org.testng.SuiteRunnerWorker.runSuite(SuiteRunnerWorker.java:53)
at org.testng.SuiteRunnerWorker.run(SuiteRunnerWorker.java:96)
at org.testng.TestNG.runSuitesSequentially(TestNG.java:1218)
at org.testng.TestNG.runSuitesLocally(TestNG.java:1140)
at org.testng.TestNG.runSuites(TestNG.java:1069)
at org.testng.TestNG.run(TestNG.java:1037)
at org.apache.maven.surefire.testng.TestNGExecutor.run(TestNGExecutor.java:284)
at org.apache.maven.surefire.testng.TestNGXmlTestSuite.execute(TestNGXmlTestSuite.java:75)
at org.apache.maven.surefire.testng.TestNGProvider.invoke(TestNGProvider.java:119)
at org.apache.maven.surefire.booter.ForkedBooter.runSuitesInProcess(ForkedBooter.java:428)
at org.apache.maven.surefire.booter.ForkedBooter.execute(ForkedBooter.java:162)
at org.apache.maven.surefire.booter.ForkedBooter.run(ForkedBooter.java:562)
at org.apache.maven.surefire.booter.ForkedBooter.main(ForkedBooter.java:548)
]]>
            </full-stacktrace>
          </exception> <!-- java.lang.Throwable -->
          <reporter-output>
          </reporter-output>
        </test-method> <!-- getUserInfo -->
      </class> <!-- com.course.cases.GetUserInfoTest -->
      <class name="com.course.cases.LoginTest">
        <test-method status="PASS" signature="beforeTest()[pri:0, instance:com.course.cases.LoginTest@31dc339b]" name="beforeTest" is-config="true" duration-ms="8381" started-at="2021-01-25T09:29:59 CST" description="测试准备工作，获取HttpClient对象" finished-at="2021-01-25T09:30:07 CST">
          <reporter-output>
          </reporter-output>
        </test-method> <!-- beforeTest -->
        <test-method status="FAIL" signature="loginTrue()[pri:0, instance:com.course.cases.LoginTest@31dc339b]" name="loginTrue" duration-ms="25817" started-at="2021-01-25T09:30:07 CST" description="用户登录成功接口测试" finished-at="2021-01-25T09:30:33 CST">
          <exception class="org.apache.ibatis.exceptions.PersistenceException">
            <message>
              <![CDATA[
### Error querying database.  Cause: com.mysql.cj.jdbc.exceptions.CommunicationsException: Communications link failure

The last packet sent successfully to the server was 0 milliseconds ago. The driver has not received any packets from the server.
### The error may exist in mapper/SQLMapper.xml
### The error may involve com.course.model.loginCase
### The error occurred while executing a query
### Cause: com.mysql.cj.jdbc.exceptions.CommunicationsException: Communications link failure

The last packet sent successfully to the server was 0 milliseconds ago. The driver has not received any packets from the server.]]>
            </message>
            <full-stacktrace>
              <![CDATA[org.apache.ibatis.exceptions.PersistenceException: 
### Error querying database.  Cause: com.mysql.cj.jdbc.exceptions.CommunicationsException: Communications link failure

The last packet sent successfully to the server was 0 milliseconds ago. The driver has not received any packets from the server.
### The error may exist in mapper/SQLMapper.xml
### The error may involve com.course.model.loginCase
### The error occurred while executing a query
### Cause: com.mysql.cj.jdbc.exceptions.CommunicationsException: Communications link failure

The last packet sent successfully to the server was 0 milliseconds ago. The driver has not received any packets from the server.
at org.apache.ibatis.exceptions.ExceptionFactory.wrapException(ExceptionFactory.java:30)
at org.apache.ibatis.session.defaults.DefaultSqlSession.selectList(DefaultSqlSession.java:149)
at org.apache.ibatis.session.defaults.DefaultSqlSession.selectList(DefaultSqlSession.java:140)
at org.apache.ibatis.session.defaults.DefaultSqlSession.selectOne(DefaultSqlSession.java:76)
at com.course.cases.LoginTest.loginTrue(LoginTest.java:41)
at sun.reflect.NativeMethodAccessorImpl.invoke0(Native Method)
at sun.reflect.NativeMethodAccessorImpl.invoke(NativeMethodAccessorImpl.java:62)
at sun.reflect.DelegatingMethodAccessorImpl.invoke(DelegatingMethodAccessorImpl.java:43)
at java.lang.reflect.Method.invoke(Method.java:498)
at org.testng.internal.MethodInvocationHelper.invokeMethod(MethodInvocationHelper.java:132)
at org.testng.internal.TestInvoker.invokeMethod(TestInvoker.java:599)
at org.testng.internal.TestInvoker.invokeTestMethod(TestInvoker.java:174)
at org.testng.internal.MethodRunner.runInSequence(MethodRunner.java:46)
at org.testng.internal.TestInvoker$MethodInvocationAgent.invoke(TestInvoker.java:822)
at org.testng.internal.TestInvoker.invokeTestMethods(TestInvoker.java:147)
at org.testng.internal.TestMethodWorker.invokeTestMethods(TestMethodWorker.java:146)
at org.testng.internal.TestMethodWorker.run(TestMethodWorker.java:128)
at java.util.ArrayList.forEach(ArrayList.java:1257)
at org.testng.TestRunner.privateRun(TestRunner.java:764)
at org.testng.TestRunner.run(TestRunner.java:585)
at org.testng.SuiteRunner.runTest(SuiteRunner.java:384)
at org.testng.SuiteRunner.runSequentially(SuiteRunner.java:378)
at org.testng.SuiteRunner.privateRun(SuiteRunner.java:337)
at org.testng.SuiteRunner.run(SuiteRunner.java:286)
at org.testng.SuiteRunnerWorker.runSuite(SuiteRunnerWorker.java:53)
at org.testng.SuiteRunnerWorker.run(SuiteRunnerWorker.java:96)
at org.testng.TestNG.runSuitesSequentially(TestNG.java:1218)
at org.testng.TestNG.runSuitesLocally(TestNG.java:1140)
at org.testng.TestNG.runSuites(TestNG.java:1069)
at org.testng.TestNG.run(TestNG.java:1037)
at org.apache.maven.surefire.testng.TestNGExecutor.run(TestNGExecutor.java:284)
at org.apache.maven.surefire.testng.TestNGXmlTestSuite.execute(TestNGXmlTestSuite.java:75)
at org.apache.maven.surefire.testng.TestNGProvider.invoke(TestNGProvider.java:119)
at org.apache.maven.surefire.booter.ForkedBooter.runSuitesInProcess(ForkedBooter.java:428)
at org.apache.maven.surefire.booter.ForkedBooter.execute(ForkedBooter.java:162)
at org.apache.maven.surefire.booter.ForkedBooter.run(ForkedBooter.java:562)
at org.apache.maven.surefire.booter.ForkedBooter.main(ForkedBooter.java:548)
Caused by: com.mysql.cj.jdbc.exceptions.CommunicationsException: Communications link failure

The last packet sent successfully to the server was 0 milliseconds ago. The driver has not received any packets from the server.
at com.mysql.cj.jdbc.exceptions.SQLError.createCommunicationsException(SQLError.java:174)
at com.mysql.cj.jdbc.exceptions.SQLExceptionsMapping.translateException(SQLExceptionsMapping.java:64)
at com.mysql.cj.jdbc.ConnectionImpl.createNewIO(ConnectionImpl.java:836)
at com.mysql.cj.jdbc.ConnectionImpl.<init>(ConnectionImpl.java:456)
at com.mysql.cj.jdbc.ConnectionImpl.getInstance(ConnectionImpl.java:246)
at com.mysql.cj.jdbc.NonRegisteringDriver.connect(NonRegisteringDriver.java:198)
at java.sql.DriverManager.getConnection(DriverManager.java:664)
at java.sql.DriverManager.getConnection(DriverManager.java:208)
at org.apache.ibatis.datasource.unpooled.UnpooledDataSource.doGetConnection(UnpooledDataSource.java:224)
at org.apache.ibatis.datasource.unpooled.UnpooledDataSource.doGetConnection(UnpooledDataSource.java:219)
at org.apache.ibatis.datasource.unpooled.UnpooledDataSource.getConnection(UnpooledDataSource.java:95)
at org.apache.ibatis.datasource.pooled.PooledDataSource.popConnection(PooledDataSource.java:432)
at org.apache.ibatis.datasource.pooled.PooledDataSource.getConnection(PooledDataSource.java:89)
at org.apache.ibatis.transaction.jdbc.JdbcTransaction.openConnection(JdbcTransaction.java:139)
at org.apache.ibatis.transaction.jdbc.JdbcTransaction.getConnection(JdbcTransaction.java:61)
at org.apache.ibatis.executor.BaseExecutor.getConnection(BaseExecutor.java:337)
at org.apache.ibatis.executor.SimpleExecutor.prepareStatement(SimpleExecutor.java:86)
at org.apache.ibatis.executor.SimpleExecutor.doQuery(SimpleExecutor.java:62)
at org.apache.ibatis.executor.BaseExecutor.queryFromDatabase(BaseExecutor.java:325)
at org.apache.ibatis.executor.BaseExecutor.query(BaseExecutor.java:156)
at org.apache.ibatis.executor.CachingExecutor.query(CachingExecutor.java:109)
at org.apache.ibatis.executor.CachingExecutor.query(CachingExecutor.java:89)
at org.apache.ibatis.session.defaults.DefaultSqlSession.selectList(DefaultSqlSession.java:147)
... 35 more
Caused by: com.mysql.cj.exceptions.CJCommunicationsException: Communications link failure

The last packet sent successfully to the server was 0 milliseconds ago. The driver has not received any packets from the server.
at sun.reflect.NativeConstructorAccessorImpl.newInstance0(Native Method)
at sun.reflect.NativeConstructorAccessorImpl.newInstance(NativeConstructorAccessorImpl.java:62)
at sun.reflect.DelegatingConstructorAccessorImpl.newInstance(DelegatingConstructorAccessorImpl.java:45)
at java.lang.reflect.Constructor.newInstance(Constructor.java:423)
at com.mysql.cj.exceptions.ExceptionFactory.createException(ExceptionFactory.java:61)
at com.mysql.cj.exceptions.ExceptionFactory.createException(ExceptionFactory.java:105)
at com.mysql.cj.exceptions.ExceptionFactory.createException(ExceptionFactory.java:151)
at com.mysql.cj.exceptions.ExceptionFactory.createCommunicationsException(ExceptionFactory.java:167)
at com.mysql.cj.protocol.a.NativeSocketConnection.connect(NativeSocketConnection.java:89)
at com.mysql.cj.NativeSession.connect(NativeSession.java:144)
at com.mysql.cj.jdbc.ConnectionImpl.connectOneTryOnly(ConnectionImpl.java:956)
at com.mysql.cj.jdbc.ConnectionImpl.createNewIO(ConnectionImpl.java:826)
... 55 more
Caused by: java.net.ConnectException: Connection timed out: connect
at java.net.DualStackPlainSocketImpl.connect0(Native Method)
at java.net.DualStackPlainSocketImpl.socketConnect(DualStackPlainSocketImpl.java:79)
at java.net.AbstractPlainSocketImpl.doConnect(AbstractPlainSocketImpl.java:350)
at java.net.AbstractPlainSocketImpl.connectToAddress(AbstractPlainSocketImpl.java:206)
at java.net.AbstractPlainSocketImpl.connect(AbstractPlainSocketImpl.java:188)
at java.net.PlainSocketImpl.connect(PlainSocketImpl.java:172)
at java.net.SocksSocketImpl.connect(SocksSocketImpl.java:392)
at java.net.Socket.connect(Socket.java:589)
at com.mysql.cj.protocol.StandardSocketFactory.connect(StandardSocketFactory.java:155)
at com.mysql.cj.protocol.a.NativeSocketConnection.connect(NativeSocketConnection.java:63)
... 58 more
]]>
            </full-stacktrace>
          </exception> <!-- org.apache.ibatis.exceptions.PersistenceException -->
          <reporter-output>
          </reporter-output>
        </test-method> <!-- loginTrue -->
        <test-method status="FAIL" signature="loginFalse()[pri:0, instance:com.course.cases.LoginTest@31dc339b]" name="loginFalse" duration-ms="21135" started-at="2021-01-25T09:30:33 CST" description="用户登录失败接口测试" finished-at="2021-01-25T09:30:54 CST">
          <exception class="org.apache.ibatis.exceptions.PersistenceException">
            <message>
              <![CDATA[
### Error querying database.  Cause: com.mysql.cj.jdbc.exceptions.CommunicationsException: Communications link failure

The last packet sent successfully to the server was 0 milliseconds ago. The driver has not received any packets from the server.
### The error may exist in mapper/SQLMapper.xml
### The error may involve com.course.model.loginCase
### The error occurred while executing a query
### Cause: com.mysql.cj.jdbc.exceptions.CommunicationsException: Communications link failure

The last packet sent successfully to the server was 0 milliseconds ago. The driver has not received any packets from the server.]]>
            </message>
            <full-stacktrace>
              <![CDATA[org.apache.ibatis.exceptions.PersistenceException: 
### Error querying database.  Cause: com.mysql.cj.jdbc.exceptions.CommunicationsException: Communications link failure

The last packet sent successfully to the server was 0 milliseconds ago. The driver has not received any packets from the server.
### The error may exist in mapper/SQLMapper.xml
### The error may involve com.course.model.loginCase
### The error occurred while executing a query
### Cause: com.mysql.cj.jdbc.exceptions.CommunicationsException: Communications link failure

The last packet sent successfully to the server was 0 milliseconds ago. The driver has not received any packets from the server.
at org.apache.ibatis.exceptions.ExceptionFactory.wrapException(ExceptionFactory.java:30)
at org.apache.ibatis.session.defaults.DefaultSqlSession.selectList(DefaultSqlSession.java:149)
at org.apache.ibatis.session.defaults.DefaultSqlSession.selectList(DefaultSqlSession.java:140)
at org.apache.ibatis.session.defaults.DefaultSqlSession.selectOne(DefaultSqlSession.java:76)
at com.course.cases.LoginTest.loginFalse(LoginTest.java:71)
at sun.reflect.NativeMethodAccessorImpl.invoke0(Native Method)
at sun.reflect.NativeMethodAccessorImpl.invoke(NativeMethodAccessorImpl.java:62)
at sun.reflect.DelegatingMethodAccessorImpl.invoke(DelegatingMethodAccessorImpl.java:43)
at java.lang.reflect.Method.invoke(Method.java:498)
at org.testng.internal.MethodInvocationHelper.invokeMethod(MethodInvocationHelper.java:132)
at org.testng.internal.TestInvoker.invokeMethod(TestInvoker.java:599)
at org.testng.internal.TestInvoker.invokeTestMethod(TestInvoker.java:174)
at org.testng.internal.MethodRunner.runInSequence(MethodRunner.java:46)
at org.testng.internal.TestInvoker$MethodInvocationAgent.invoke(TestInvoker.java:822)
at org.testng.internal.TestInvoker.invokeTestMethods(TestInvoker.java:147)
at org.testng.internal.TestMethodWorker.invokeTestMethods(TestMethodWorker.java:146)
at org.testng.internal.TestMethodWorker.run(TestMethodWorker.java:128)
at java.util.ArrayList.forEach(ArrayList.java:1257)
at org.testng.TestRunner.privateRun(TestRunner.java:764)
at org.testng.TestRunner.run(TestRunner.java:585)
at org.testng.SuiteRunner.runTest(SuiteRunner.java:384)
at org.testng.SuiteRunner.runSequentially(SuiteRunner.java:378)
at org.testng.SuiteRunner.privateRun(SuiteRunner.java:337)
at org.testng.SuiteRunner.run(SuiteRunner.java:286)
at org.testng.SuiteRunnerWorker.runSuite(SuiteRunnerWorker.java:53)
at org.testng.SuiteRunnerWorker.run(SuiteRunnerWorker.java:96)
at org.testng.TestNG.runSuitesSequentially(TestNG.java:1218)
at org.testng.TestNG.runSuitesLocally(TestNG.java:1140)
at org.testng.TestNG.runSuites(TestNG.java:1069)
at org.testng.TestNG.run(TestNG.java:1037)
at org.apache.maven.surefire.testng.TestNGExecutor.run(TestNGExecutor.java:284)
at org.apache.maven.surefire.testng.TestNGXmlTestSuite.execute(TestNGXmlTestSuite.java:75)
at org.apache.maven.surefire.testng.TestNGProvider.invoke(TestNGProvider.java:119)
at org.apache.maven.surefire.booter.ForkedBooter.runSuitesInProcess(ForkedBooter.java:428)
at org.apache.maven.surefire.booter.ForkedBooter.execute(ForkedBooter.java:162)
at org.apache.maven.surefire.booter.ForkedBooter.run(ForkedBooter.java:562)
at org.apache.maven.surefire.booter.ForkedBooter.main(ForkedBooter.java:548)
Caused by: com.mysql.cj.jdbc.exceptions.CommunicationsException: Communications link failure

The last packet sent successfully to the server was 0 milliseconds ago. The driver has not received any packets from the server.
at com.mysql.cj.jdbc.exceptions.SQLError.createCommunicationsException(SQLError.java:174)
at com.mysql.cj.jdbc.exceptions.SQLExceptionsMapping.translateException(SQLExceptionsMapping.java:64)
at com.mysql.cj.jdbc.ConnectionImpl.createNewIO(ConnectionImpl.java:836)
at com.mysql.cj.jdbc.ConnectionImpl.<init>(ConnectionImpl.java:456)
at com.mysql.cj.jdbc.ConnectionImpl.getInstance(ConnectionImpl.java:246)
at com.mysql.cj.jdbc.NonRegisteringDriver.connect(NonRegisteringDriver.java:198)
at java.sql.DriverManager.getConnection(DriverManager.java:664)
at java.sql.DriverManager.getConnection(DriverManager.java:208)
at org.apache.ibatis.datasource.unpooled.UnpooledDataSource.doGetConnection(UnpooledDataSource.java:224)
at org.apache.ibatis.datasource.unpooled.UnpooledDataSource.doGetConnection(UnpooledDataSource.java:219)
at org.apache.ibatis.datasource.unpooled.UnpooledDataSource.getConnection(UnpooledDataSource.java:95)
at org.apache.ibatis.datasource.pooled.PooledDataSource.popConnection(PooledDataSource.java:432)
at org.apache.ibatis.datasource.pooled.PooledDataSource.getConnection(PooledDataSource.java:89)
at org.apache.ibatis.transaction.jdbc.JdbcTransaction.openConnection(JdbcTransaction.java:139)
at org.apache.ibatis.transaction.jdbc.JdbcTransaction.getConnection(JdbcTransaction.java:61)
at org.apache.ibatis.executor.BaseExecutor.getConnection(BaseExecutor.java:337)
at org.apache.ibatis.executor.SimpleExecutor.prepareStatement(SimpleExecutor.java:86)
at org.apache.ibatis.executor.SimpleExecutor.doQuery(SimpleExecutor.java:62)
at org.apache.ibatis.executor.BaseExecutor.queryFromDatabase(BaseExecutor.java:325)
at org.apache.ibatis.executor.BaseExecutor.query(BaseExecutor.java:156)
at org.apache.ibatis.executor.CachingExecutor.query(CachingExecutor.java:109)
at org.apache.ibatis.executor.CachingExecutor.query(CachingExecutor.java:89)
at org.apache.ibatis.session.defaults.DefaultSqlSession.selectList(DefaultSqlSession.java:147)
... 35 more
Caused by: com.mysql.cj.exceptions.CJCommunicationsException: Communications link failure

The last packet sent successfully to the server was 0 milliseconds ago. The driver has not received any packets from the server.
at sun.reflect.NativeConstructorAccessorImpl.newInstance0(Native Method)
at sun.reflect.NativeConstructorAccessorImpl.newInstance(NativeConstructorAccessorImpl.java:62)
at sun.reflect.DelegatingConstructorAccessorImpl.newInstance(DelegatingConstructorAccessorImpl.java:45)
at java.lang.reflect.Constructor.newInstance(Constructor.java:423)
at com.mysql.cj.exceptions.ExceptionFactory.createException(ExceptionFactory.java:61)
at com.mysql.cj.exceptions.ExceptionFactory.createException(ExceptionFactory.java:105)
at com.mysql.cj.exceptions.ExceptionFactory.createException(ExceptionFactory.java:151)
at com.mysql.cj.exceptions.ExceptionFactory.createCommunicationsException(ExceptionFactory.java:167)
at com.mysql.cj.protocol.a.NativeSocketConnection.connect(NativeSocketConnection.java:89)
at com.mysql.cj.NativeSession.connect(NativeSession.java:144)
at com.mysql.cj.jdbc.ConnectionImpl.connectOneTryOnly(ConnectionImpl.java:956)
at com.mysql.cj.jdbc.ConnectionImpl.createNewIO(ConnectionImpl.java:826)
... 55 more
Caused by: java.net.ConnectException: Connection timed out: connect
at java.net.DualStackPlainSocketImpl.connect0(Native Method)
at java.net.DualStackPlainSocketImpl.socketConnect(DualStackPlainSocketImpl.java:79)
at java.net.AbstractPlainSocketImpl.doConnect(AbstractPlainSocketImpl.java:350)
at java.net.AbstractPlainSocketImpl.connectToAddress(AbstractPlainSocketImpl.java:206)
at java.net.AbstractPlainSocketImpl.connect(AbstractPlainSocketImpl.java:188)
at java.net.PlainSocketImpl.connect(PlainSocketImpl.java:172)
at java.net.SocksSocketImpl.connect(SocksSocketImpl.java:392)
at java.net.Socket.connect(Socket.java:589)
at com.mysql.cj.protocol.StandardSocketFactory.connect(StandardSocketFactory.java:155)
at com.mysql.cj.protocol.a.NativeSocketConnection.connect(NativeSocketConnection.java:63)
... 58 more
]]>
            </full-stacktrace>
          </exception> <!-- org.apache.ibatis.exceptions.PersistenceException -->
          <reporter-output>
          </reporter-output>
        </test-method> <!-- loginFalse -->
      </class> <!-- com.course.cases.LoginTest -->
      <class name="com.course.cases.AddUserTest">
        <test-method status="SKIP" signature="addUser()[pri:0, instance:com.course.cases.AddUserTest@544fe44c]" name="addUser" duration-ms="0" depends-on-groups="loginTrue" started-at="2021-01-25T09:30:54 CST" description="添加用户接口测试" finished-at="2021-01-25T09:30:54 CST">
          <exception class="java.lang.Throwable">
            <message>
              <![CDATA[Method AddUserTest.addUser()[pri:0, instance:com.course.cases.AddUserTest@544fe44c] depends on not successfully finished methods in group "loginTrue"]]>
            </message>
            <full-stacktrace>
              <![CDATA[java.lang.Throwable: Method AddUserTest.addUser()[pri:0, instance:com.course.cases.AddUserTest@544fe44c] depends on not successfully finished methods in group "loginTrue"
at org.testng.internal.TestInvoker.invokeTestMethods(TestInvoker.java:102)
at org.testng.internal.TestMethodWorker.invokeTestMethods(TestMethodWorker.java:146)
at org.testng.internal.TestMethodWorker.run(TestMethodWorker.java:128)
at java.util.ArrayList.forEach(ArrayList.java:1257)
at org.testng.TestRunner.privateRun(TestRunner.java:764)
at org.testng.TestRunner.run(TestRunner.java:585)
at org.testng.SuiteRunner.runTest(SuiteRunner.java:384)
at org.testng.SuiteRunner.runSequentially(SuiteRunner.java:378)
at org.testng.SuiteRunner.privateRun(SuiteRunner.java:337)
at org.testng.SuiteRunner.run(SuiteRunner.java:286)
at org.testng.SuiteRunnerWorker.runSuite(SuiteRunnerWorker.java:53)
at org.testng.SuiteRunnerWorker.run(SuiteRunnerWorker.java:96)
at org.testng.TestNG.runSuitesSequentially(TestNG.java:1218)
at org.testng.TestNG.runSuitesLocally(TestNG.java:1140)
at org.testng.TestNG.runSuites(TestNG.java:1069)
at org.testng.TestNG.run(TestNG.java:1037)
at org.apache.maven.surefire.testng.TestNGExecutor.run(TestNGExecutor.java:284)
at org.apache.maven.surefire.testng.TestNGXmlTestSuite.execute(TestNGXmlTestSuite.java:75)
at org.apache.maven.surefire.testng.TestNGProvider.invoke(TestNGProvider.java:119)
at org.apache.maven.surefire.booter.ForkedBooter.runSuitesInProcess(ForkedBooter.java:428)
at org.apache.maven.surefire.booter.ForkedBooter.execute(ForkedBooter.java:162)
at org.apache.maven.surefire.booter.ForkedBooter.run(ForkedBooter.java:562)
at org.apache.maven.surefire.booter.ForkedBooter.main(ForkedBooter.java:548)
]]>
            </full-stacktrace>
          </exception> <!-- java.lang.Throwable -->
          <reporter-output>
          </reporter-output>
        </test-method> <!-- addUser -->
      </class> <!-- com.course.cases.AddUserTest -->
      <class name="com.course.cases.GetUserListTest">
        <test-method status="SKIP" signature="getUserList()[pri:0, instance:com.course.cases.GetUserListTest@71318ec4]" name="getUserList" duration-ms="0" depends-on-groups="loginTrue" started-at="2021-01-25T09:30:54 CST" description="获取性别为男的用户信息" finished-at="2021-01-25T09:30:54 CST">
          <exception class="java.lang.Throwable">
            <message>
              <![CDATA[Method GetUserListTest.getUserList()[pri:0, instance:com.course.cases.GetUserListTest@71318ec4] depends on not successfully finished methods in group "loginTrue"]]>
            </message>
            <full-stacktrace>
              <![CDATA[java.lang.Throwable: Method GetUserListTest.getUserList()[pri:0, instance:com.course.cases.GetUserListTest@71318ec4] depends on not successfully finished methods in group "loginTrue"
at org.testng.internal.TestInvoker.invokeTestMethods(TestInvoker.java:102)
at org.testng.internal.TestMethodWorker.invokeTestMethods(TestMethodWorker.java:146)
at org.testng.internal.TestMethodWorker.run(TestMethodWorker.java:128)
at java.util.ArrayList.forEach(ArrayList.java:1257)
at org.testng.TestRunner.privateRun(TestRunner.java:764)
at org.testng.TestRunner.run(TestRunner.java:585)
at org.testng.SuiteRunner.runTest(SuiteRunner.java:384)
at org.testng.SuiteRunner.runSequentially(SuiteRunner.java:378)
at org.testng.SuiteRunner.privateRun(SuiteRunner.java:337)
at org.testng.SuiteRunner.run(SuiteRunner.java:286)
at org.testng.SuiteRunnerWorker.runSuite(SuiteRunnerWorker.java:53)
at org.testng.SuiteRunnerWorker.run(SuiteRunnerWorker.java:96)
at org.testng.TestNG.runSuitesSequentially(TestNG.java:1218)
at org.testng.TestNG.runSuitesLocally(TestNG.java:1140)
at org.testng.TestNG.runSuites(TestNG.java:1069)
at org.testng.TestNG.run(TestNG.java:1037)
at org.apache.maven.surefire.testng.TestNGExecutor.run(TestNGExecutor.java:284)
at org.apache.maven.surefire.testng.TestNGXmlTestSuite.execute(TestNGXmlTestSuite.java:75)
at org.apache.maven.surefire.testng.TestNGProvider.invoke(TestNGProvider.java:119)
at org.apache.maven.surefire.booter.ForkedBooter.runSuitesInProcess(ForkedBooter.java:428)
at org.apache.maven.surefire.booter.ForkedBooter.execute(ForkedBooter.java:162)
at org.apache.maven.surefire.booter.ForkedBooter.run(ForkedBooter.java:562)
at org.apache.maven.surefire.booter.ForkedBooter.main(ForkedBooter.java:548)
]]>
            </full-stacktrace>
          </exception> <!-- java.lang.Throwable -->
          <reporter-output>
          </reporter-output>
        </test-method> <!-- getUserList -->
      </class> <!-- com.course.cases.GetUserListTest -->
    </test> <!-- 用户管理系统测试用例 -->
  </suite> <!-- 用户管理系统测试套件 -->
</testng-results>
